Workbook

Sheet Raw_VN30_Statistic
A1: No. | B1: Date | C1: Symbol | D1: Basic | E1: Open | F1: Close | G1: High | H1: Low | I1: Average | J1: Change (+/-) | K1: % | L1: Order Matching Vol | M1: Order Matching Val | N1: Put-Through Vol | O1: Put-Through Val | P1: Total Vol | Q1: Total Val | R1: Market Cap.
A2: 1 | B2: 46080 | C2: ACB | D2: 24.45 | E2: 24.45 | F2: 24.55 | G2: 24.6 | H2: 24.2 | I2: 24.44 | J2: 100 | K2: 0.41 | L2: 11051000 | M2: 270195 | N2: 3849900 | O2: 94145 | P2: 14900900 | Q2: 364340 | R2: 126104920
A3: 2 | B3: 46080 | C3: BID | D3: 48.45 | E3: 48.45 | F3: 47.9 | G3: 49.1 | H3: 47.5 | I3: 48.03 | J3: -550 | K3: -1.14 | L3: 6519700 | M3: 312959 | N3: 0 | O3: 0 | P3: 6519700 | Q3: 312959 | R3: 336323236
A4: 3 | B4: 46080 | C4: CTG | D4: 38.5 | E4: 38.45 | F4: 38.25 | G4: 38.45 | H4: 38.05 | I4: 38.18 | J4: -250 | K4: -0.65 | L4: 8888400 | M4: 339416 | N4: 2069000 | O4: 79446 | P4: 10957400 | Q4: 418862 | R4: 297085632
A5: 4 | B5: 46080 | C5: DGC | D5: 73.6 | E5: 73.3 | F5: 73.8 | G5: 74.5 | H5: 72 | I5: 73.24 | J5: 200 | K5: 0.27 | L5: 3393400 | M5: 248780 | N5: 1032900 | O5: 78286 | P5: 4426300 | Q5: 327067 | R5: 28027647
A6: 5 | B6: 46080 | C6: FPT | D6: 90.5 | E6: 91 | F6: 92.9 | G6: 93.5 | H6: 90.3 | I6: 91.88 | J6: 2400 | K6: 2.65 | L6: 18705600 | M6: 1721107 | N6: 800000 | O6: 67360 | P6: 19505600 | Q6: 1788467 | R6: 158255812
A7: 6 | B7: 46080 | C7: GAS | D7: 106 | E7: 106 | F7: 107.9 | G7: 111.9 | H7: 105.5 | I7: 107.54 | J7: 1900 | K7: 1.79 | L7: 2827100 | M7: 304213 | N7: 0 | O7: 0 | P7: 2827100 | Q7: 304213 | R7: 260357279
A8: 7 | B8: 46080 | C8: GVR | D8: 40.8 | E8: 40.8 | F8: 40 | G8: 42.3 | H8: 39.8 | I8: 40.78 | J8: -800 | K8: -1.96 | L8: 6357900 | M8: 259188 | N8: 0 | O8: 0 | P8: 6357900 | Q8: 259188 | R8: 160000000
A9: 8 | B9: 46080 | C9: HDB | D9: 28.4 | E9: 28.4 | F9: 27.95 | G9: 28.4 | H9: 27.95 | I9: 28.08 | J9: -450 | K9: -1.58 | L9: 13120700 | M9: 368404 | N9: 7953471 | O9: 222686 | P9: 21074171 | Q9: 591089 | R9: 139897473
A10: 9 | B10: 46080 | C10: HPG | D10: 29.4 | E10: 29.35 | F10: 28.8 | G10: 29.4 | H10: 28.8 | I10: 29.03 | J10: -600 | K10: -2.04 | L10: 47306500 | M10: 1372206 | N10: 2750000 | O10: 80791 | P10: 50056500 | Q10: 1452997 | R10: 221053417
A11: 10 | B11: 46080 | C11: LPB | D11: 43.15 | E11: 43.5 | F11: 43.05 | G11: 44.3 | H11: 42.75 | I11: 43.25 | J11: -100 | K11: -0.23 | L11: 1473700 | M11: 63793 | N11: 36000 | O11: 1555 | P11: 1509700 | Q11: 65348 | R11: 128602494
A12: 11 | B12: 46080 | C12: MBB | D12: 28.8 | E12: 28.75 | F12: 28.5 | G12: 28.85 | H12: 28.5 | I12: 28.66 | J12: -300 | K12: -1.04 | L12: 14848500 | M12: 425291 | N12: 4685100 | O12: 136076 | P12: 19533600 | Q12: 561367 | R12: 229567497
A13: 12 | B13: 46080 | C13: MSN | D13: 80.4 | E13: 80.5 | F13: 79 | G13: 80.6 | H13: 79 | I13: 79.67 | J13: -1400 | K13: -1.74 | L13: 5053900 | M13: 402550 | N13: 0 | O13: 0 | P13: 5053900 | Q13: 402550 | R13: 120118862
... A18: 17 | B18: 46080 | C18: SSB | D18: 17 | E18: 16.95 | F18: 16.9 | G18: 17 | H18: 16.75 | I18: 16.86 | J18: -100 | K18: -0.59 | L18: 1992800 | M18: 33590 | N18: 0 | O18: 0 | P18: 1992800 | Q18: 33590 | R18: 48080500
A19: 18 | B19: 46080 | C19: SSI | D19: 32.4 | E19: 32.5 | F19: 32.4 | G19: 32.95 | H19: 32.1 | I19: 32.58 | J19: - | K19: - | L19: 37296900 | M19: 1215217 | N19: 62380 | O19: 1920 | P19: 37359280 | Q19: 1217136 | R19: 80711567
A20: 19 | B20: 46080 | C20: STB | D20: 67 | E20: 66.9 | F20: 65.5 | G20: 67.2 | H20: 65.5 | I20: 66.12 | J20: -1500 | K20: -2.24 | L20: 7079500 | M20: 468180 | N20: 0 | O20: 0 | P20: 7079500 | Q20: 468180 | R20: 123481629
A21: 20 | B21: 46080 | C21: TCB | D21: 36.45 | E21: 36.05 | F21: 36.25 | G21: 36.4 | H21: 35.85 | I21: 36.09 | J21: -200 | K21: -0.55 | L21: 7958700 | M21: 287267 | N21: 13339500 | O21: 489545 | P21: 21298200 | Q21: 776812 | R21: 256876215
A22: 21 | B22: 46080 | C22: TPB | D22: 18.35 | E22: 18.45 | F22: 18.4 | G22: 18.7 | H22: 18.25 | I22: 18.48 | J22: 50 | K22: 0.27 | L22: 17459800 | M22: 322709 | N22: 800000 | O22: 14826 | P22: 18259800 | Q22: 337535 | R22: 51042462
A23: 22 | B23: 46080 | C23: VCB | D23: 65.4 | E23: 65.5 | F23: 64.9 | G23: 66.4 | H23: 64.8 | I23: 65.19 | J23: -500 | K23: -0.76 | L23: 8831200 | M23: 575608 | N23: 107000 | O23: 6614 | P23: 8938200 | Q23: 582222 | R23: 542283314
A24: 23 | B24: 46080 | C24: VHM | D24: 107.6 | E24: 108 | F24: 108 | G24: 109.5 | H24: 104.6 | I24: 107.03 | J24: 400 | K24: 0.37 | L24: 4915000 | M24: 526590 | N24: 1472500 | O24: 160032 | P24: 6387500 | Q24: 686622 | R24: 443600496
A25: 24 | B25: 46080 | C25: VIB | D25: 17.4 | E25: 17.4 | F25: 17.3 | G25: 17.45 | H25: 17.3 | I25: 17.35 | J25: -100 | K25: -0.57 | L25: 2778500 | M25: 48203 | N25: 0 | O25: 0 | P25: 2778500 | Q25: 48203 | R25: 58889299
A26: 25 | B26: 46080 | C26: VIC | D26: 168.9 | E26: 169.1 | F26: 172 | G26: 178.5 | H26: 168 | I26: 173.39 | J26: 3100 | K26: 1.84 | L26: 3624400 | M26: 628942 | N26: 800000 | O26: 137600 | P26: 4424400 | Q26: 766542 | R26: 1330160606
A27: 26 | B27: 46080 | C27: VJC | D27: 178.5 | E27: 177.8 | F27: 175.8 | G27: 178.5 | H27: 175.2 | I27: 176.5 | J27: -2700 | K27: -1.51 | L27: 1133900 | M27: 200153 | N27: 0 | O27: 0 | P27: 1133900 | Q27: 200153 | R27: 104005273
A28: 27 | B28: 46080 | C28: VNM | D28: 70.6 | E28: 70.2 | F28: 68.2 | G28: 70.6 | H28: 68 | I28: 68.92 | J28: -2400 | K28: -3.4 | L28: 13371400 | M28: 921102 | N28: 20000 | O28: 1350 | P28: 13391400 | Q28: 922452 | R28: 142534961
A29: 28 | B29: 46080 | C29: VPB | D29: 28.9 | E29: 29.05 | F29: 28.95 | G29: 29.45 | H29: 28.75 | I29: 29.1 | J29: 50 | K29: 0.17 | L29: 18002900 | M29: 523346 | N29: 0 | O29: 0 | P29: 18002900 | Q29: 523346 | R29: 229687088
A30: 29 | B30: 46080 | C30: VPL | D30: 81.7 | E30: 82.5 | F30: 83.5 | G30: 84.1 | H30: 80.5 | I30: 82.44 | J30: 1800 | K30: 2.2 | L30: 223600 | M30: 18504 | N30: 0 | O30: 0 | P30: 223600 | Q30: 18504 | R30: 149740581
A31: 30 | B31: 46080 | C31: VRE | D31: 29.75 | E31: 29.8 | F31: 29.05 | G31: 29.8 | H31: 29.05 | I31: 29.27 | J31: -700 | K31: -2.35 | L31: 3100400 | M31: 90661 | N31: 20000 | O31: 591 | P31: 3120400 | Q31: 91252 | R31: 66010850

Sheet Raw_VN30_Influence
A1: No. | B1: Stock | C1: Price | D1: Change | E1: Outstanding Shares | F1: Market Cap. | G1: Proportion | H1: %influence | I1: Influence points
A2: 1 | B2: FPT | C2: 92900 | D2: 2,400 (+2.65%) | E2: 1703507121 | F2: 118725092376099 | G2: 8.9719 | H2: 0.2378 | I2: 4.9211
A3: 2 | B3: VIC | C3: 172000 | D3: 3,100 (+1.84%) | E3: 7706031024 | F3: 142139899926367 | G3: 10.7413 | H3: 0.1976 | I3: 4.0908
A4: 3 | B4: GAS | C4: 107900 | D4: 1,900 (+1.79%) | E4: 2412949756 | F4: 13017863933620 | G4: 0.9837 | H4: 0.0176 | I4: 0.3645
A5: 4 | B5: ACB | C5: 24550 | D5: 100 (+0.41%) | E5: 5136656599 | F5: 48513823582942 | G5: 3.6661 | H5: 0.015 | I5: 0.3111
A6: 5 | B6: VPL | C6: 83500 | D6: 1,800 (+2.20%) | E6: 1793300377 | F6: 8479060426277 | G6: 0.6407 | H6: 0.0141 | I6: 0.2917
A7: 6 | B7: VHM | C7: 108000 | D7: 400 (+0.37%) | E7: 4107412004 | F7: 50237756220924 | G7: 3.7964 | H7: 0.014 | I7: 0.2907
A8: 7 | B8: VPB | C8: 28950 | D8: 50 (+0.17%) | E8: 7933923601 | F8: 62373825684885 | G8: 4.7135 | H8: 0.008 | I8: 0.1659
A9: 8 | B9: DGC | C9: 73800 | D9: 200 (+0.27%) | E9: 379778413 | F9: 16816588127640 | G9: 1.2708 | H9: 0.0034 | I9: 0.071
A10: 9 | B10: PLX | C10: 57800 | D10: 300 (+0.52%) | E10: 1270592235 | F10: 7344023118300 | G10: 0.5549 | H10: 0.0029 | I10: 0.0597
A11: 10 | B11: TPB | C11: 18400 | D11: 50 (+0.27%) | E11: 2774046873 | F11: 12706000180964 | G11: 0.9601 | H11: 0.0026 | I11: 0.0537
A12: 11 | B12: SSI | C12: 32400 | D12: 0 (0%) | E12: 2491097752 | F12: 25571038709152 | G12: 1.9323 | H12: 0 | I12: 0
A13: 12 | B13: SSB | C13: 16900 | D13: -100 (-0.59%) | E13: 2845000000 | F13: 10880617150000 | G13: 0.8222 | H13: -0.0049 | I13: -0.1004
... A31: 30 | B31: HPG | C31: 28800 | D31: -600 (-2.04%) | E31: 7675465855 | F31: 121579379143200 | G31: 9.1876 | H31: -0.1874 | I31: -3.8794

Sheet Dashboard
A1: VN30 AutoScore Dashboard (Paste data in Raw_HOSE_Paste)
A2: Key metrics | D2: Signals | G2: MARKET HEALTH
A3: Breadth Up: | B3: =SUM(AutoScore!P2:P31) -> 10 | D3: MSI Score (Spot Context): | E3: =ROUND( 0.28*$E$11 +0.34*$E$13 +0.12*$E$12 +0.16*$E$22 +0.06*(100-$E$14) +0.04*$E$23,0) -> 40 | G3: MSI Score: | H3: =Dashboard!E3 -> 40
A4: Breadth Down: | B4: =SUM(AutoScore!Q2:Q31) -> 19 | D4: BullTrapRisk (0-100): | E4: =MAX(0,MIN(100,ROUND(100*(0.35*$B$6+0.25*IFERROR(ABS($B$14)/MAX(ABS($B$11),0.0001),0)+0.2*$B$19+0.2*$B$16-0.15*$B$18-0.05*$B$5),0))) -> 71 | G4: Composite: | H4: =Dashboard!E15 -> 37
A5: % Up: | B5: =IFERROR(SUM(AutoScore!P2:P31)/30,0) -> 0.33333333 | D5: WashoutChance (0-100): | E5: =MAX(0,MIN(100,ROUND(100*(0.45*$B$6 + 0.25*$B$19 + 0.2*IFERROR(SUM(AutoScore!$S$2:$S$31)/30,0) + 0.1*MIN(ABS($B$11)/3,1)),0))) -> 49 | G5: Breadth score: | H5: =Dashboard!E11 -> 35
A6: % Down: | B6: =IFERROR(SUM(AutoScore!Q2:Q31)/30,0) -> 0.63333333 | D6: SqueezeChance (0-100): | E6: =MAX(0,MIN(100,ROUND(100*(0.45*$B$5+0.25*$B$18+0.2*(1-$B$19)+0.1*MIN(ABS($B$11)/3,1)-0.2*IFERROR(ABS($B$14)/MAX(ABS($B$11),0.0001),0)),0))) -> 12 | G6: Trend score: | H6: =Dashboard!E13 -> 47.516361
A7: Near High Count: | B7: =SUM(AutoScore!N2:N31) -> 3 | D7: ATC Pull Up chance: | E7: =IF(E6>=60,"High",IF(E6>=40,"Medium","Low")) -> Low | G7: NearHigh score: | H7: =Dashboard!E12 -> 31.666667
A8: Near Low Count: | B8: =SUM(AutoScore!O2:O31) -> 14 | D8: ATC Dump chance: | E8: =IF(E4>=60,"High",IF(E4>=40,"Medium","Low")) -> High | G8: Distortion: | H8: =Dashboard!E14 -> 56.736799
A9: Up > 1% count: | B9: =SUM(AutoScore!R2:R31) -> 4 | G9: INDEX CONTROL
A10: Down < -1% count: | B10: =SUM(AutoScore!S2:S31) -> 12 | D10: Score components (0-100) | G10: Weighted Breadth: | H10: =Dashboard!E22 -> 36
A11: WeightedMove (sum): | B11: =SUM(AutoScore!T2:T31) -> -0.24836386 | D11: Breadth score: | E11: =MAX(0,MIN(100, 50 + 50*(B5-B6))) -> 35 | G11: Influence Concentration: | H11: =Dashboard!E23 -> 57
A12: Weighted range-pos (sum w*pos): | B12: =SUM(AutoScore!U2:U31) -> 0.31906658 | D12: NearHigh-Low score: | E12: =MAX(0,MIN(100, 50 + 50*(B18-B19))) -> 31.666667 | G12: Top3 Share: | H12: {=ROUND(100*IFERROR((LARGE(ABS(AutoScore!$V$2:$V$31),1)+LARGE(ABS(AutoScore!$V$2:$V$31),2)+LARGE(ABS(AutoScore!$V$2:$V$31),3))/SUMPRODUCT(ABS(AutoScore!$V$2:$V$31)),0),0)} -> 43
A13: Bank WeightedMove: | B13: =SUMPRODUCT(AutoScore!T2:T31,AutoScore!K2:K31) -> -0.26801172 | D13: Trend score (weighted move): | E13: =MAX(0,MIN(100, 50 + 10*B11)) -> 47.516361 | G13: Top Heavyweight Influence Share: | H13: {=ROUND(100*IFERROR( SUMPRODUCT((AutoScore!$L$2:$L$31=1)*ABS(AutoScore!$V$2:$V$31)) / SUMPRODUCT(ABS(AutoScore!$V$2:$V$31)),0),0)} -> 50
A14: Heavyweights WeightedMove: | B14: =SUMPRODUCT(AutoScore!T2:T31,AutoScore!L2:L31) -> 0.21265802 | D14: Distortion score (Heavyweights - Rest): | E14: =MAX(0,MIN(100, 50 + 10*(B14-B15))) -> 56.736799 | G14: Bank Share: | H14: {=ROUND(100*IFERROR( SUMPRODUCT((AutoScore!$K$2:$K$31=1)*ABS(AutoScore!$V$2:$V$31)) / SUMPRODUCT(ABS(AutoScore!$V$2:$V$31)),0),0)} -> 26
A15: Non-Heavyweights WeightedMove: | B15: {=SUMPRODUCT((AutoScore!L2:L31=0)*AutoScore!T2:T31)} -> -0.46102187 | D15: Composite Score: | E15: =ROUND(0.25*E11 + 0.4*E12 + 0.2*E13 + 0.15*(100-E14),0) -> 37 | G15: Top3 Proportion Share: | H15: =SUM(LARGE(AutoScore!$X$2:$X$31,1),LARGE(AutoScore!$X$2:$X$31,2),LARGE(AutoScore!$X$2:$X$31,3))/100 -> 0.279833
A16: Bank Share of TotalMove: | B16: =IFERROR(SUMPRODUCT(AutoScore!T2:T31,AutoScore!K2:K31)/SUM(AutoScore!T2:T31),0) -> 1.0791092 | D16: State label: | E16: =IF(E15>=70,"BULL / SQUEEZE RISK",IF(E15<=30,"BEAR / WASHOUT RISK","SIDEWAY / TRAP ZONE")) -> SIDEWAY / TRAP ZONE | G16: Top3 %Influence Share: | H16: {=ROUND(SUM(LARGE(AutoScore!$W$2:$W$31,{1,2,3})),2)} -> 0.68
A17: Heavyweights Share of TotalMove: | B17: =IFERROR(SUMPRODUCT(AutoScore!T2:T31,AutoScore!L2:L31)/SUM(AutoScore!T2:T31),0) -> -0.85623575 | D17: Bull-trap risk: | E17: =IF(AND(E13>=65,E11<=45,E14>=65),"HIGH",IF(AND(E13>=60,E14>=60),"MED","LOW")) -> LOW | G17: Rotation Delta: | H17: =(H16-H15)*100 -> 40.0167
A18: % Near High: | B18: =IFERROR(SUM(AutoScore!N2:N31)/COUNTA(AutoScore!A2:A31),0) -> 0.1 | D18: Washout opportunity: | E18: =IF(AND(E13<=35,B19>=0.45),"HIGH",IF(AND(E13<=40,B19>=0.35),"MED","LOW")) -> LOW | G18: RISK & EVENT PROBABILITY
A19: % Near Low: | B19: =IFERROR(SUM(AutoScore!O2:O31)/COUNTA(AutoScore!A2:A31),0) -> 0.46666667 | D19: Squeeze trigger watch: | E19: =IF(AND(E13>=60,B18>=0.45,B19<=0.25),"HIGH",IF(E13>=55,"MED","LOW")) -> LOW | G19: Index Dependency Risk (0–100) | H19: {=IFERROR(ROUND(100*ABS(SUMIFS(AutoScore!$V$2:$V$31,AutoScore!$L$2:$L$31,1))/SUMPRODUCT(ABS(AutoScore!$V$2:$V$31)),0),0)} -> 11
A20: Up/Down: | B20: =TEXT(B5,"0%")&" / "&TEXT(B6,"0%") -> 33% / 63% | D20: MSI Score vs Composite Score: | E20: =IF($E$3-$E$15>=MAX(4,MIN(8,ROUND($E$13/15,0))),"Internal>Surface(Bull ẩn)",IF($E$3-$E$15<=-MAX(4,MIN(8,ROUND($E$13/15,0))),"Surface>Internals(Kéo trụ/méo)","ALIGNED")) -> ALIGNED | G20: BullTrap: | H20: =Dashboard!E17 -> LOW
A21: NearHigh/NearLow: | B21: =TEXT(B18,"0%")&" / "&TEXT(B19,"0%") -> 10% / 47% | D21: Composite Score Evalution: | E21: =IF($E$15="","", IF($E$15>=70,"Continuation Up", IF($E$15<=30,"Pullback", "Digest"))) -> Digest | G21: Washout: | H21: =Dashboard!E18 -> LOW
A22: Heavyweights vs Rest (w*%chg): | B22: =TEXT(B14,"0.00")&" / "&TEXT(B15,"0.00") -> 0.21 / -0.46 | D22: Weighted Breadth score (0-100): | E22: =MAX(0,MIN(100,ROUND(100*$B$24,0))) -> 36 | G22: Squeeze: | H22: =Dashboard!E19 -> LOW
A23: MSI (simple): | B23: =IF($E$3>=80,"STRONG BULL",IF($E$3>=70,"BULL",IF($E$3>=60,"WEAK BULL",IF($E$3>=45,"NEUTRAL",IF($E$3>=30,"DISTRIBUTION","BEAR"))))) -> DISTRIBUTION | D23: Influence Concentration score: | E23: {=MAX(0,MIN(100,ROUND(100*(1-((LARGE(ABS(AutoScore!$V$2:$V$31),1)+LARGE(ABS(AutoScore!$V$2:$V$31),2)+LARGE(ABS(AutoScore!$V$2:$V$31),3))/SUMPRODUCT(ABS(AutoScore!$V$2:$V$31)))),0)))} -> 57 | G23: Regime: | H23: =IF($H$3>=80,"STRONG BULL",IF($H$3>=70,"BULL",IF($H$3>=60,"WEAK BULL",IF($H$3>=45,"NEUTRAL",IF($H$3>=30,"DISTRIBUTION","BEAR"))))) -> DISTRIBUTION
A24: Weighted Up Share: | B24: =IFERROR(SUMIF(AutoScore!$G$2:$G$31,">0",AutoScore!$J$2:$J$31),0) -> 0.36299872 | G24: Structure: | H24: =IF(AND($H$10>=70,$H$11>=60,$H$19<=40),"Broad-based expansion",IF(AND($H$10>=70,OR($H$11<55,$H$19>55)),"Top-heavy rally",IF(AND($H$10<60,$H$3>=60),"Narrow participation",IF(AND($H$3<45,$H$10<45),"Risk-off","Mixed / digestion")))) -> Risk-off
A25: Weighted Down Share: | B25: =IFERROR(SUMIF(AutoScore!$G$2:$G$31,"<0",AutoScore!$J$2:$J$31),0) -> 0.52580084 | G25: Risk Flag: | H25: =IF(OR($H$20="HIGH",$H$21="HIGH"),"High risk regime",IF($H$22="HIGH","Squeeze risk elevated","Risk contained")) -> Risk contained
G26: FINAL VERDICT: | H26: =$H$23&" | "&$H$24&IF($H$14>=45," | Bank-led","")&" | "&$H$25 &" | "&$H$27 -> DISTRIBUTION | Risk-off | Risk contained | WAIT CONFIRMATION
G27: ACTION BIAS: | H27: =IF(OR($H$20="HIGH",$H$21="HIGH"), "STAND ASIDE (trap/washout high)", IF(AND($H$3>=70,$H$10>=65,$H$11>=60,$H$19<=45,$H$22<>"LOW"), "CONTINUATION BIAS (trend-friendly)", IF(AND($H$3>=60,$H$4>=60), "SCALP / RANGE until breakout", "WAIT CONFIRMATION"))) -> WAIT CONFIRMATION
H28: =IF($H$10>=70,"WHY: Weighted breadth strong","WHY: Participation not strong") &" / "&IF($H$19<=40,"low dependency","dependency elevated") &" / "&IF($H$11>=60,"concentration ok","top3 too dominant") -> WHY: Participation not strong / low dependency / top3 too dominant
G29: PREFERRED SETUP: | H29: =IF(OR($H$20="HIGH",$H$21="HIGH"), "NO TRADE / CAPITAL PROTECTION", IF(AND($H$3>=75,$H$10>=70,$H$11>=60,$H$19<=40,$H$22="HIGH"), "BREAKOUT LONG (trend expansion)", IF(AND($H$3>=70,$H$10>=65,$H$11>=60,$H$19<=45), "PULLBACK LONG (buy HL / EMA reclaim)", IF(AND($H$3<=30,$H$10<=40,$H$11>=60,$H$19<=45), "BREAKDOWN SHORT (trend expansion)", IF(AND($H$3<=40,$H$10<=45), "PULLBACK SHORT (sell LH / EMA reject)", IF(AND($H$3>=60,$H$3<70), "SCALP (range / intraday only)", "WAIT / OBSERVE" )))))) -> PULLBACK SHORT (sell LH / EMA reject)
A32: How to use:
A33: 1) Paste/overwrite 30 rows into Raw_HOSE_Paste (A1:Q31).
A34: 2) Paste/overwrite 30 rows into Raw_VN30_Influence_Paste (A1:I31).
A35: 2) Go to Dashboard to see scores; AutoScore_Table shows per-ticker flags.
A36: 3) Optional: fill Weight(optional) in AutoScore_Table col J to override MarketCap weights.

Sheet Raw_OI
A1: No. | B1: Date | C1: Open | D1: Close | E1: High | F1: Low | G1: Volume | H1: Put-through | I1: Open interest (OI) | J1: Settlement price | K1: Change | L1: ΔClose | M1: ΔOI | N1: OI_Quadrant | O1: ValidDay | P1: DayRank
A2: =ROW()-ROW(tblOI[[#Headers],[No.]]) -> 1 | B2: 46080 | C2: 2067 | D2: 2061.3 | E2: 2072.5 | F2: 2054.5 | G2: 102348 | H2: 0 | I2: 34991 | J2: 2061.3 | K2: -5.8(-0.28) | L2: {=IFERROR(tblOI[[#This Row],[Close]]-INDEX(tblOI[Close],tblOI[[#This Row],[No.]]+1),"")} -> 5.6 | M2: {=IFERROR(tblOI[[#This Row],[Open interest (OI)]]-INDEX(tblOI[Open interest (OI)],tblOI[[#This Row],[No.]]+1),"")} -> 6868 | N2: =IF(OR(tblOI[[#This Row],[ΔClose]]="",tblOI[[#This Row],[ΔOI]]=""),"", IF(AND(tblOI[[#This Row],[ΔClose]]>0,tblOI[[#This Row],[ΔOI]]>0),"BUILD LONG", IF(AND(tblOI[[#This Row],[ΔClose]]<0,tblOI[[#This Row],[ΔOI]]>0),"BUILD SHORT", IF(AND(tblOI[[#This Row],[ΔClose]]>0,tblOI[[#This Row],[ΔOI]]<0),"SHORT COVER", IF(AND(tblOI[[#This Row],[ΔClose]]<0,tblOI[[#This Row],[ΔOI]]<0),"LONG UNWIND","-"))))) -> BUILD LONG | O2: =IF(tblOI[[#This Row],[OI_Quadrant]]="","",1) -> 1 | P2: =IF(tblOI[[#This Row],[ValidDay]]="","",SUMIFS(tblOI[ValidDay],tblOI[No.],"<="&tblOI[[#This Row],[No.]])) -> 1
A3: =ROW()-ROW(tblOI[[#Headers],[No.]]) -> 2 | B3: 46079 | C3: 2043.7 | D3: 2055.7 | E3: 2065.8 | F3: 2043.3 | G3: 121314 | H3: 32 | I3: 28123 | J3: 2055.7 | K3: 9.2(0.45) | L3: {=IFERROR(tblOI[[#This Row],[Close]]-INDEX(tblOI[Close],tblOI[[#This Row],[No.]]+1),"")} -> 9.2 | M3: {=IFERROR(tblOI[[#This Row],[Open interest (OI)]]-INDEX(tblOI[Open interest (OI)],tblOI[[#This Row],[No.]]+1),"")} -> -5186 | N3: =IF(OR(tblOI[[#This Row],[ΔClose]]="",tblOI[[#This Row],[ΔOI]]=""),"", IF(AND(tblOI[[#This Row],[ΔClose]]>0,tblOI[[#This Row],[ΔOI]]>0),"BUILD LONG", IF(AND(tblOI[[#This Row],[ΔClose]]<0,tblOI[[#This Row],[ΔOI]]>0),"BUILD SHORT", IF(AND(tblOI[[#This Row],[ΔClose]]>0,tblOI[[#This Row],[ΔOI]]<0),"SHORT COVER", IF(AND(tblOI[[#This Row],[ΔClose]]<0,tblOI[[#This Row],[ΔOI]]<0),"LONG UNWIND","-"))))) -> SHORT COVER | O3: =IF(tblOI[[#This Row],[OI_Quadrant]]="","",1) -> 1 | P3: =IF(tblOI[[#This Row],[ValidDay]]="","",SUMIFS(tblOI[ValidDay],tblOI[No.],"<="&tblOI[[#This Row],[No.]])) -> 2
A4: =ROW()-ROW(tblOI[[#Headers],[No.]]) -> 3 | B4: 46078 | C4: 2055 | D4: 2046.5 | E4: 2066.8 | F4: 2044.2 | G4: 211342 | H4: 0 | I4: 33309 | J4: 2046.5 | K4: 0(0) | L4: {=IFERROR(tblOI[[#This Row],[Close]]-INDEX(tblOI[Close],tblOI[[#This Row],[No.]]+1),"")} -> 0 | M4: {=IFERROR(tblOI[[#This Row],[Open interest (OI)]]-INDEX(tblOI[Open interest (OI)],tblOI[[#This Row],[No.]]+1),"")} -> -2353 | N4: =IF(OR(tblOI[[#This Row],[ΔClose]]="",tblOI[[#This Row],[ΔOI]]=""),"", IF(AND(tblOI[[#This Row],[ΔClose]]>0,tblOI[[#This Row],[ΔOI]]>0),"BUILD LONG", IF(AND(tblOI[[#This Row],[ΔClose]]<0,tblOI[[#This Row],[ΔOI]]>0),"BUILD SHORT", IF(AND(tblOI[[#This Row],[ΔClose]]>0,tblOI[[#This Row],[ΔOI]]<0),"SHORT COVER", IF(AND(tblOI[[#This Row],[ΔClose]]<0,tblOI[[#This Row],[ΔOI]]<0),"LONG UNWIND","-"))))) -> - | O4: =IF(tblOI[[#This Row],[OI_Quadrant]]="","",1) -> 1 | P4: =IF(tblOI[[#This Row],[ValidDay]]="","",SUMIFS(tblOI[ValidDay],tblOI[No.],"<="&tblOI[[#This Row],[No.]])) -> 3
A5: =ROW()-ROW(tblOI[[#Headers],[No.]]) -> 4 | B5: 46077 | C5: 2041.1 | D5: 2046.5 | E5: 2046.9 | F5: 2032.2 | G5: 163164 | H5: 70 | I5: 35662 | J5: 2046.5 | K5: 2.5(0.12) | L5: {=IFERROR(tblOI[[#This Row],[Close]]-INDEX(tblOI[Close],tblOI[[#This Row],[No.]]+1),"")} -> 2.5 | M5: {=IFERROR(tblOI[[#This Row],[Open interest (OI)]]-INDEX(tblOI[Open interest (OI)],tblOI[[#This Row],[No.]]+1),"")} -> 12871 | N5: =IF(OR(tblOI[[#This Row],[ΔClose]]="",tblOI[[#This Row],[ΔOI]]=""),"", IF(AND(tblOI[[#This Row],[ΔClose]]>0,tblOI[[#This Row],[ΔOI]]>0),"BUILD LONG", IF(AND(tblOI[[#This Row],[ΔClose]]<0,tblOI[[#This Row],[ΔOI]]>0),"BUILD SHORT", IF(AND(tblOI[[#This Row],[ΔClose]]>0,tblOI[[#This Row],[ΔOI]]<0),"SHORT COVER", IF(AND(tblOI[[#This Row],[ΔClose]]<0,tblOI[[#This Row],[ΔOI]]<0),"LONG UNWIND","-"))))) -> BUILD LONG | O5: =IF(tblOI[[#This Row],[OI_Quadrant]]="","",1) -> 1 | P5: =IF(tblOI[[#This Row],[ValidDay]]="","",SUMIFS(tblOI[ValidDay],tblOI[No.],"<="&tblOI[[#This Row],[No.]])) -> 4
A6: =ROW()-ROW(tblOI[[#Headers],[No.]]) -> 5 | B6: 46076 | C6: 2033 | D6: 2044 | E6: 2049.1 | F6: 2031.5 | G6: 128143 | H6: 0 | I6: 22791 | J6: 2044 | K6: 24.2(1.2) | L6: {=IFERROR(tblOI[[#This Row],[Close]]-INDEX(tblOI[Close],tblOI[[#This Row],[No.]]+1),"")} -> 24.2 | M6: {=IFERROR(tblOI[[#This Row],[Open interest (OI)]]-INDEX(tblOI[Open interest (OI)],tblOI[[#This Row],[No.]]+1),"")} -> 7452 | N6: =IF(OR(tblOI[[#This Row],[ΔClose]]="",tblOI[[#This Row],[ΔOI]]=""),"", IF(AND(tblOI[[#This Row],[ΔClose]]>0,tblOI[[#This Row],[ΔOI]]>0),"BUILD LONG", IF(AND(tblOI[[#This Row],[ΔClose]]<0,tblOI[[#This Row],[ΔOI]]>0),"BUILD SHORT", IF(AND(tblOI[[#This Row],[ΔClose]]>0,tblOI[[#This Row],[ΔOI]]<0),"SHORT COVER", IF(AND(tblOI[[#This Row],[ΔClose]]<0,tblOI[[#This Row],[ΔOI]]<0),"LONG UNWIND","-"))))) -> BUILD LONG | O6: =IF(tblOI[[#This Row],[OI_Quadrant]]="","",1) -> 1 | P6: =IF(tblOI[[#This Row],[ValidDay]]="","",SUMIFS(tblOI[ValidDay],tblOI[No.],"<="&tblOI[[#This Row],[No.]])) -> 5
A7: =ROW()-ROW(tblOI[[#Headers],[No.]]) -> 6 | B7: 46066 | C7: 2021 | D7: 2019.8 | E7: 2025 | F7: 2012 | G7: 20817 | H7: 0 | I7: 15339 | J7: 2019.8 | K7: -7.2(-0.36) | L7: {=IFERROR(tblOI[[#This Row],[Close]]-INDEX(tblOI[Close],tblOI[[#This Row],[No.]]+1),"")} -> 9.3 | M7: {=IFERROR(tblOI[[#This Row],[Open interest (OI)]]-INDEX(tblOI[Open interest (OI)],tblOI[[#This Row],[No.]]+1),"")} -> -14497 | N7: =IF(OR(tblOI[[#This Row],[ΔClose]]="",tblOI[[#This Row],[ΔOI]]=""),"", IF(AND(tblOI[[#This Row],[ΔClose]]>0,tblOI[[#This Row],[ΔOI]]>0),"BUILD LONG", IF(AND(tblOI[[#This Row],[ΔClose]]<0,tblOI[[#This Row],[ΔOI]]>0),"BUILD SHORT", IF(AND(tblOI[[#This Row],[ΔClose]]>0,tblOI[[#This Row],[ΔOI]]<0),"SHORT COVER", IF(AND(tblOI[[#This Row],[ΔClose]]<0,tblOI[[#This Row],[ΔOI]]<0),"LONG UNWIND","-"))))) -> SHORT COVER | O7: =IF(tblOI[[#This Row],[OI_Quadrant]]="","",1) -> 1 | P7: =IF(tblOI[[#This Row],[ValidDay]]="","",SUMIFS(tblOI[ValidDay],tblOI[No.],"<="&tblOI[[#This Row],[No.]])) -> 6
A8: =ROW()-ROW(tblOI[[#Headers],[No.]]) -> 7 | B8: 46066 | C8: 2020.8 | D8: 2010.5 | E8: 2022.4 | F8: 2009 | G8: 143785 | H8: 0 | I8: 29836 | J8: 2010.5 | K8: -10.5(-0.52) | L8: {=IFERROR(tblOI[[#This Row],[Close]]-INDEX(tblOI[Close],tblOI[[#This Row],[No.]]+1),"")} -> -10.5 | M8: {=IFERROR(tblOI[[#This Row],[Open interest (OI)]]-INDEX(tblOI[Open interest (OI)],tblOI[[#This Row],[No.]]+1),"")} -> -6757 | N8: =IF(OR(tblOI[[#This Row],[ΔClose]]="",tblOI[[#This Row],[ΔOI]]=""),"", IF(AND(tblOI[[#This Row],[ΔClose]]>0,tblOI[[#This Row],[ΔOI]]>0),"BUILD LONG", IF(AND(tblOI[[#This Row],[ΔClose]]<0,tblOI[[#This Row],[ΔOI]]>0),"BUILD SHORT", IF(AND(tblOI[[#This Row],[ΔClose]]>0,tblOI[[#This Row],[ΔOI]]<0),"SHORT COVER", IF(AND(tblOI[[#This Row],[ΔClose]]<0,tblOI[[#This Row],[ΔOI]]<0),"LONG UNWIND","-"))))) -> LONG UNWIND | O8: =IF(tblOI[[#This Row],[OI_Quadrant]]="","",1) -> 1 | P8: =IF(tblOI[[#This Row],[ValidDay]]="","",SUMIFS(tblOI[ValidDay],tblOI[No.],"<="&tblOI[[#This Row],[No.]])) -> 7
A9: =ROW()-ROW(tblOI[[#Headers],[No.]]) -> 8 | B9: 46065 | C9: 2024.3 | D9: 2021 | E9: 2028 | F9: 2015.4 | G9: 131142 | H9: 0 | I9: 36593 | J9: 2021 | K9: 3(0.15) | L9: {=IFERROR(tblOI[[#This Row],[Close]]-INDEX(tblOI[Close],tblOI[[#This Row],[No.]]+1),"")} -> 3 | M9: {=IFERROR(tblOI[[#This Row],[Open interest (OI)]]-INDEX(tblOI[Open interest (OI)],tblOI[[#This Row],[No.]]+1),"")} -> -712 | N9: =IF(OR(tblOI[[#This Row],[ΔClose]]="",tblOI[[#This Row],[ΔOI]]=""),"", IF(AND(tblOI[[#This Row],[ΔClose]]>0,tblOI[[#This Row],[ΔOI]]>0),"BUILD LONG", IF(AND(tblOI[[#This Row],[ΔClose]]<0,tblOI[[#This Row],[ΔOI]]>0),"BUILD SHORT", IF(AND(tblOI[[#This Row],[ΔClose]]>0,tblOI[[#This Row],[ΔOI]]<0),"SHORT COVER", IF(AND(tblOI[[#This Row],[ΔClose]]<0,tblOI[[#This Row],[ΔOI]]<0),"LONG UNWIND","-"))))) -> SHORT COVER | O9: =IF(tblOI[[#This Row],[OI_Quadrant]]="","",1) -> 1 | P9: =IF(tblOI[[#This Row],[ValidDay]]="","",SUMIFS(tblOI[ValidDay],tblOI[No.],"<="&tblOI[[#This Row],[No.]])) -> 8
A10: =ROW()-ROW(tblOI[[#Headers],[No.]]) -> 9 | B10: 46064 | C10: 1967.7 | D10: 2018 | E10: 2018.3 | F10: 1967.2 | G10: 288938 | H10: 40 | I10: 37305 | J10: 2018 | K10: 51.9(2.64) | L10: {=IFERROR(tblOI[[#This Row],[Close]]-INDEX(tblOI[Close],tblOI[[#This Row],[No.]]+1),"")} -> 51.9 | M10: {=IFERROR(tblOI[[#This Row],[Open interest (OI)]]-INDEX(tblOI[Open interest (OI)],tblOI[[#This Row],[No.]]+1),"")} -> -5530 | N10: =IF(OR(tblOI[[#This Row],[ΔClose]]="",tblOI[[#This Row],[ΔOI]]=""),"", IF(AND(tblOI[[#This Row],[ΔClose]]>0,tblOI[[#This Row],[ΔOI]]>0),"BUILD LONG", IF(AND(tblOI[[#This Row],[ΔClose]]<0,tblOI[[#This Row],[ΔOI]]>0),"BUILD SHORT", IF(AND(tblOI[[#This Row],[ΔClose]]>0,tblOI[[#This Row],[ΔOI]]<0),"SHORT COVER", IF(AND(tblOI[[#This Row],[ΔClose]]<0,tblOI[[#This Row],[ΔOI]]<0),"LONG UNWIND","-"))))) -> SHORT COVER | O10: =IF(tblOI[[#This Row],[OI_Quadrant]]="","",1) -> 1 | P10: =IF(tblOI[[#This Row],[ValidDay]]="","",SUMIFS(tblOI[ValidDay],tblOI[No.],"<="&tblOI[[#This Row],[No.]])) -> 9
A11: =ROW()-ROW(tblOI[[#Headers],[No.]]) -> 10 | B11: 46063 | C11: 1960.8 | D11: 1966.1 | E11: 1980 | F11: 1930 | G11: 283888 | H11: 0 | I11: 42835 | J11: 1966.1 | K11: 10.4(0.53) | L11: {=IFERROR(tblOI[[#This Row],[Close]]-INDEX(tblOI[Close],tblOI[[#This Row],[No.]]+1),"")} -> 10.4 | M11: {=IFERROR(tblOI[[#This Row],[Open interest (OI)]]-INDEX(tblOI[Open interest (OI)],tblOI[[#This Row],[No.]]+1),"")} -> 2152 | N11: =IF(OR(tblOI[[#This Row],[ΔClose]]="",tblOI[[#This Row],[ΔOI]]=""),"", IF(AND(tblOI[[#This Row],[ΔClose]]>0,tblOI[[#This Row],[ΔOI]]>0),"BUILD LONG", IF(AND(tblOI[[#This Row],[ΔClose]]<0,tblOI[[#This Row],[ΔOI]]>0),"BUILD SHORT", IF(AND(tblOI[[#This Row],[ΔClose]]>0,tblOI[[#This Row],[ΔOI]]<0),"SHORT COVER", IF(AND(tblOI[[#This Row],[ΔClose]]<0,tblOI[[#This Row],[ΔOI]]<0),"LONG UNWIND","-"))))) -> BUILD LONG | O11: =IF(tblOI[[#This Row],[OI_Quadrant]]="","",1) -> 1 | P11: =IF(tblOI[[#This Row],[ValidDay]]="","",SUMIFS(tblOI[ValidDay],tblOI[No.],"<="&tblOI[[#This Row],[No.]])) -> 10
A12: =ROW()-ROW(tblOI[[#Headers],[No.]]) -> 11 | B12: 46062 | C12: 1964.3 | D12: 1955.7 | E12: 1970.4 | F12: 1952.3 | G12: 171339 | H12: 0 | I12: 40683 | J12: 1955.7 | K12: 4.4(0.23) | L12: {=IFERROR(tblOI[[#This Row],[Close]]-INDEX(tblOI[Close],tblOI[[#This Row],[No.]]+1),"")} -> 4.4 | M12: {=IFERROR(tblOI[[#This Row],[Open interest (OI)]]-INDEX(tblOI[Open interest (OI)],tblOI[[#This Row],[No.]]+1),"")} -> -4160 | N12: =IF(OR(tblOI[[#This Row],[ΔClose]]="",tblOI[[#This Row],[ΔOI]]=""),"", IF(AND(tblOI[[#This Row],[ΔClose]]>0,tblOI[[#This Row],[ΔOI]]>0),"BUILD LONG", IF(AND(tblOI[[#This Row],[ΔClose]]<0,tblOI[[#This Row],[ΔOI]]>0),"BUILD SHORT", IF(AND(tblOI[[#This Row],[ΔClose]]>0,tblOI[[#This Row],[ΔOI]]<0),"SHORT COVER", IF(AND(tblOI[[#This Row],[ΔClose]]<0,tblOI[[#This Row],[ΔOI]]<0),"LONG UNWIND","-"))))) -> SHORT COVER | O12: =IF(tblOI[[#This Row],[OI_Quadrant]]="","",1) -> 1 | P12: =IF(tblOI[[#This Row],[ValidDay]]="","",SUMIFS(tblOI[ValidDay],tblOI[No.],"<="&tblOI[[#This Row],[No.]])) -> 11
A13: =ROW()-ROW(tblOI[[#Headers],[No.]]) -> 12 | B13: 46059 | C13: 1961 | D13: 1951.3 | E13: 1971.8 | F13: 1948.6 | G13: 290480 | H13: 48 | I13: 44843 | J13: 1951.3 | K13: -20.9(-1.06) | L13: {=IFERROR(tblOI[[#This Row],[Close]]-INDEX(tblOI[Close],tblOI[[#This Row],[No.]]+1),"")} -> -20.9 | M13: {=IFERROR(tblOI[[#This Row],[Open interest (OI)]]-INDEX(tblOI[Open interest (OI)],tblOI[[#This Row],[No.]]+1),"")} -> -1011 | N13: =IF(OR(tblOI[[#This Row],[ΔClose]]="",tblOI[[#This Row],[ΔOI]]=""),"", IF(AND(tblOI[[#This Row],[ΔClose]]>0,tblOI[[#This Row],[ΔOI]]>0),"BUILD LONG", IF(AND(tblOI[[#This Row],[ΔClose]]<0,tblOI[[#This Row],[ΔOI]]>0),"BUILD SHORT", IF(AND(tblOI[[#This Row],[ΔClose]]>0,tblOI[[#This Row],[ΔOI]]<0),"SHORT COVER", IF(AND(tblOI[[#This Row],[ΔClose]]<0,tblOI[[#This Row],[ΔOI]]<0),"LONG UNWIND","-"))))) -> LONG UNWIND | O13: =IF(tblOI[[#This Row],[OI_Quadrant]]="","",1) -> 1 | P13: =IF(tblOI[[#This Row],[ValidDay]]="","",SUMIFS(tblOI[ValidDay],tblOI[No.],"<="&tblOI[[#This Row],[No.]])) -> 12
... A15: =ROW()-ROW(tblOI[[#Headers],[No.]]) -> 14 | B15: 46057 | C15: 1999.8 | D15: 2010 | E15: 2010 | F15: 1982.1 | G15: 300562 | H15: 0 | I15: 44551 | J15: 2010 | K15: 10(0.5) | L15: {=IFERROR(tblOI[[#This Row],[Close]]-INDEX(tblOI[Close],tblOI[[#This Row],[No.]]+1),"")} | M15: {=IFERROR(tblOI[[#This Row],[Open interest (OI)]]-INDEX(tblOI[Open interest (OI)],tblOI[[#This Row],[No.]]+1),"")} | N15: =IF(OR(tblOI[[#This Row],[ΔClose]]="",tblOI[[#This Row],[ΔOI]]=""),"", IF(AND(tblOI[[#This Row],[ΔClose]]>0,tblOI[[#This Row],[ΔOI]]>0),"BUILD LONG", IF(AND(tblOI[[#This Row],[ΔClose]]<0,tblOI[[#This Row],[ΔOI]]>0),"BUILD SHORT", IF(AND(tblOI[[#This Row],[ΔClose]]>0,tblOI[[#This Row],[ΔOI]]<0),"SHORT COVER", IF(AND(tblOI[[#This Row],[ΔClose]]<0,tblOI[[#This Row],[ΔOI]]<0),"LONG UNWIND","-"))))) | O15: =IF(tblOI[[#This Row],[OI_Quadrant]]="","",1) | P15: =IF(tblOI[[#This Row],[ValidDay]]="","",SUMIFS(tblOI[ValidDay],tblOI[No.],"<="&tblOI[[#This Row],[No.]]))
L16: =IF(OR(B15="",B17="",B15=B17,I15="",I17=""),"",I15-I17) | M16: =IF(OR(B15="",B17="",B15=B17,I15="",I17=""),"",I15-I17) | N16: =IF(OR(L16="",M16=""),"", IF(AND(L16>0,M16>0),"BUILD LONG", IF(AND(L16<0,M16>0),"BUILD SHORT", IF(AND(L16>0,M16<0),"SHORT COVER", IF(AND(L16<0,M16<0),"LONG UNWIND","-"))))) | O16: =IF($N16="","",1) | P16: =IF($O16="","",COUNT($O$6:$O16))
B21: OI 3D Bias | C21: =IF(COUNT(tblOI[DayRank])<3,"OI 3D: NA", IF(COUNTIFS(tblOI[DayRank],"<=3",tblOI[OI_Quadrant],"BUILD LONG")>=2,"OI 3D: LONG BUILD", IF(COUNTIFS(tblOI[DayRank],"<=3",tblOI[OI_Quadrant],"BUILD SHORT")>=2,"OI 3D: SHORT BUILD", IF(COUNTIFS(tblOI[DayRank],"<=3",tblOI[OI_Quadrant],"SHORT COVER")>=2,"OI 3D: SHORT COVER", IF(COUNTIFS(tblOI[DayRank],"<=3",tblOI[OI_Quadrant],"LONG UNWIND")>=2,"OI 3D: LONG UNWIND", "OI 3D: MIXED"))))) -> OI 3D: MIXED

Sheet History_Log
A1: VN30 AutoScore — History Log
A3: How to use (no macro):
A4: Paste Raw_HOSE_Paste daily → Dashboard updates → copy row 13 (A:V)and Paste Values into next empty row below, then copy row 13 (W,X,Y) and Paste Formulas into that new row.
A8: Auto stats (computed from logged outcomes)
A9: Bucket (MSI label) | C9: N | D9: Cont.Up % | E9: Digest % | F9: Pullback %
A10: STRONG BULL | C10: =COUNTIF($D$14:$D$1996,"STRONG BULL") -> 0 | D10: =IF($C10=0,"",COUNTIFS($D$14:$D$1996,"STRONG BULL",$Z$14:$Z$1996,"Continuation Up")/$C10) | E10: =IF($C10=0,"",COUNTIFS($D$14:$D$1996,"STRONG BULL",$Z$14:$Z$1996,"Digest")/$C10) | F10: =IF($C10=0,"",COUNTIFS($D$14:$D$1996,"STRONG BULL",$Z$14:$Z$1996,"Pullback")/$C10)
A11: BULL | C11: =COUNTIF($D$14:$D$1996,"BULL") -> 1 | D11: =IF($C11=0,"",COUNTIFS($D$14:$D$1996,"BULL",$Y$14:$Y$1996,"Continuation Up")/$C11) -> 0 | E11: =IF($C11=0,"",COUNTIFS($D$14:$D$1996,"BULL",$Z$14:$Z$1996,"Digest")/$C11) -> 0 | F11: =IF($C11=0,"",COUNTIFS($D$14:$D$1996,"BULL",$Y$14:$Y$1996,"Pullback")/$C11) -> 0
A12: Date | B12: Time | C12: MSI Score | D12: MSI Label | E12: Composite Score | F12: State Label | G12: Breadth Up | H12: Breadth Down | I12: % Up | J12: % Down | K12: % Near High | L12: % Near Low | M12: WeightedMove Sum | N12: Trend Score | O12: Distortion Score | P12: Bank Share | Q12: Heavyweights Share | R12: BullTrapRisk | S12: WashoutChance | T12: SqueezeChance | U12: Bank WeightedMove | V12: Heavyweights WeightedMove | W12: Non-Heavyweights WeightedMove | X12: NextDay WeightedMove | Y12: NextDay Composite | Z12: Outcome T+1
A13: =TODAY() -> 46082 | B13: =TIME(HOUR(NOW()), MINUTE(NOW()), SECOND(NOW())) -> 0.57420139 | C13: =Dashboard!$E$3 -> 40 | D13: =Dashboard!$B$23 -> DISTRIBUTION | E13: =Dashboard!E15 -> 37 | F13: =Dashboard!E16 -> SIDEWAY / TRAP ZONE | G13: =Dashboard!B3 -> 10 | H13: =Dashboard!B4 -> 19 | I13: =Dashboard!B5 -> 0.33333333 | J13: =Dashboard!B6 -> 0.63333333 | K13: =Dashboard!B18 -> 0.1 | L13: =Dashboard!B19 -> 0.46666667 | M13: =Dashboard!B11 -> -0.24836386 | N13: =Dashboard!E13 -> 47.516361 | O13: =Dashboard!E14 -> 56.736799 | P13: =Dashboard!B16 -> 1.0791092 | Q13: =Dashboard!B17 -> -0.85623575 | R13: =Dashboard!E17 -> LOW | S13: =Dashboard!E5 -> 49 | T13: =Dashboard!E6 -> 12 | U13: =Dashboard!B13 -> -0.26801172 | V13: =Dashboard!B14 -> 0.21265802 | W13: =Dashboard!B15 -> -0.46102187 | X13: =IF($A14="","",$M14) -> 1.9084064 | Y13: =IF($A14="","",$E14) -> 73 | Z13: =IF($A14="","",IF(X13>=0.5,"Continuation Up",IF(X13<=-0.5,"Pullback","Digest"))) -> Continuation Up
A14: 46076 | B14: 0.61519676 | C14: 75 | D14: BULL | E14: 73 | F14: BULL / SQUEEZE RISK | G14: 26 | H14: 3 | I14: 0.86666667 | J14: 0.1 | K14: 0.36666667 | L14: 0.033333333 | M14: 1.9084064 | N14: 69.084064 | O14: 56.922453 | P14: 0.41571689 | Q14: 0.68136739 | R14: LOW | S14: 13 | T14: 60 | U14: 0.79335677 | V14: 1.3003259 | W14: 0.60808051 | X14: =IF($A15="","",$M15) -> 0.7917938 | Y14: =IF($A15="","",$E15) -> 54 | Z14: =IF($A15="","",IF(X14>=0.5,"Continuation Up",IF(X14<=-0.5,"Pullback","Digest"))) -> Continuation Up
A15: 46077 | B15: 0.61519676 | C15: 57 | D15: NEUTRAL | E15: 54 | F15: SIDEWAY / TRAP ZONE | G15: 16 | H15: 14 | I15: 0.53333333 | J15: 0.46666667 | K15: 0.26666667 | L15: 0.2 | M15: 0.7917938 | N15: 57.917938 | O15: 51.090529 | P15: -0.031916175 | Q15: 0.56886443 | R15: LOW | S15: 33 | T15: 38 | U15: -0.025271029 | V15: 0.45042333 | W15: 0.34137047 | X15: =IF($A16="","",$M16) -> 0.013815983 | Y15: =IF($A16="","",$E16) -> 51 | Z15: =IF($A16="","",IF(X15>=0.5,"Continuation Up",IF(X15<=-0.5,"Pullback","Digest"))) -> Digest
A16: 46078 | B16: 0.61519676 | C16: 52 | D16: NEUTRAL | E16: 51 | F16: SIDEWAY / TRAP ZONE | G16: 17 | H16: 13 | I16: 0.56666667 | J16: 0.43333333 | K16: 0.13333333 | L16: 0.2 | M16: 0.013815983 | N16: 50.13816 | O16: 45.265792 | P16: 32.651624 | Q16: -16.633083 | R16: LOW | S16: 29 | T16: 0 | U16: 0.45111427 | V16: -0.22980239 | W16: 0.24361837 | X16: =IF($A17="","",$M17) -> 0.53692775 | Y16: =IF($A17="","",$E17) -> 48 | Z16: =IF($A17="","",IF(X16>=0.5,"Continuation Up",IF(X16<=-0.5,"Pullback","Digest"))) -> Continuation Up
A17: 46079 | B17: 0.41230324 | C17: 55 | D17: NEUTRAL | E17: 48 | F17: SIDEWAY / TRAP ZONE | G17: 15 | H17: 10 | I17: 0.5 | J17: 0.33333333 | K17: 0.1 | L17: 0.3 | M17: 0.53692775 | N17: 55.369278 | O17: 56.027616 | P17: 0.25353594 | Q17: 1.0613061 | R17: LOW | S17: 29 | T17: 20 | U17: 0.13613048 | V17: 0.5698447 | W17: -0.20728822 | X17: =IF($A18="","",$M18) -> 0.50660459 | Y17: =IF($A18="","",$E18) -> 34 | Z17: =IF($A18="","",IF(X17>=0.5,"Continuation Up",IF(X17<=-0.5,"Pullback","Digest"))) -> Continuation Up
A18: 46079 | B18: 0.48533565 | C18: 42 | D18: DISTRIBUTION | E18: 34 | F18: SIDEWAY / TRAP ZONE | G18: 9 | H18: 18 | I18: 0.3 | J18: 0.6 | K18: 0.1 | L18: 0.7 | M18: 0.50660459 | N18: 55.066046 | O18: 60.131366 | P18: -0.15216202 | Q18: 1.4999284 | R18: LOW | S18: 53 | T18: 0 | U18: -0.077085976 | V18: 0.75987061 | W18: -0.25326602 | X18: =IF($A19="","",$M19) -> 1.0362835 | Y18: =IF($A19="","",$E19) -> 54 | Z18: =IF($A19="","",IF(X18>=0.5,"Continuation Up",IF(X18<=-0.5,"Pullback","Digest"))) -> Continuation Up
A19: 46079 | B19: 0.61696759 | C19: 60 | D19: WEAK BULL | E19: 54 | F19: SIDEWAY / TRAP ZONE | G19: 16 | H19: 10 | I19: 0.53333333 | J19: 0.33333333 | K19: 0.2 | L19: 0.13333333 | M19: 1.0362835 | N19: 60.362835 | O19: 59.850276 | P19: 0.15495539 | Q19: 0.97526932 | R19: LOW | S19: 25 | T19: 30 | U19: 0.16057772 | V19: 1.0106555 | W19: 0.025627994 | X19: =IF($A20="","",$M20) -> -0.14296731 | Y19: =IF($A20="","",$E20) -> 41 | Z19: =IF($A20="","",IF(X19>=0.5,"Continuation Up",IF(X19<=-0.5,"Pullback","Digest"))) -> Digest
A20: 46080 | B20: 0.48293981 | C20: 39 | D20: DISTRIBUTION | E20: 41 | F20: SIDEWAY / TRAP ZONE | G20: 8 | H20: 19 | I20: 0.26666667 | J20: 0.63333333 | K20: 0.066666667 | L20: 0.23333333 | M20: -0.14296731 | N20: 48.570327 | O20: 53.319943 | P20: 0.83818401 | Q20: -0.66108479 | R20: LOW | S20: 39 | T20: 16 | U20: -0.11983292 | V20: 0.094513518 | W20: -0.23748083 | X20: =IF($A21="","",$M21) -> -0.26610662 | Y20: =IF($A21="","",$E21) -> 37 | Z20: =IF($A21="","",IF(X20>=0.5,"Continuation Up",IF(X20<=-0.5,"Pullback","Digest"))) -> Digest
A21: 46080 | B21: 0.6456713 | C21: 41 | D21: DISTRIBUTION | E21: 37 | F21: SIDEWAY / TRAP ZONE | G21: 10 | H21: 19 | I21: 0.33333333 | J21: 0.63333333 | K21: 0.1 | L21: 0.46666667 | M21: -0.26610662 | N21: 47.338934 | O21: 57.492227 | P21: 1.1090562 | Q21: -0.90774918 | R21: LOW | S21: 49 | T21: 11 | U21: -0.29512718 | V21: 0.24155806 | W21: -0.50766468 | X21: =IF($A22="","",$M22) | Y21: =IF($A22="","",$E22) | Z21: =IF($A22="","",IF(X21>=0.5,"Continuation Up",IF(X21<=-0.5,"Pullback","Digest")))
X22: =IF($A23="","",$M23) | Y22: =IF($A23="","",$E23) | Z22: =IF($A23="","",IF(X22>=0.5,"Continuation Up",IF(X22<=-0.5,"Pullback","Digest")))
X23: =IF($A24="","",$M24) | Y23: =IF($A24="","",$E24) | Z23: =IF($A24="","",IF(X23>=0.5,"Continuation Up",IF(X23<=-0.5,"Pullback","Digest")))
X24: =IF($A25="","",$M25) | Y24: =IF($A25="","",$E25) | Z24: =IF($A25="","",IF(X24>=0.5,"Continuation Up",IF(X24<=-0.5,"Pullback","Digest")))
X25: =IF($A26="","",$M26) | Y25: =IF($A26="","",$E26) | Z25: =IF($A26="","",IF(X25>=0.5,"Continuation Up",IF(X25<=-0.5,"Pullback","Digest")))
X26: =IF($A27="","",$M27) | Y26: =IF($A27="","",$E27) | Z26: =IF($A27="","",IF(X26>=0.5,"Continuation Up",IF(X26<=-0.5,"Pullback","Digest")))
X27: =IF($A28="","",$M28) | Y27: =IF($A28="","",$E28) | Z27: =IF($A28="","",IF(X27>=0.5,"Continuation Up",IF(X27<=-0.5,"Pullback","Digest")))
X28: =IF($A29="","",$M29) | Y28: =IF($A29="","",$E29) | Z28: =IF($A29="","",IF(X28>=0.5,"Continuation Up",IF(X28<=-0.5,"Pullback","Digest")))
X29: =IF($A30="","",$M30) | Y29: =IF($A30="","",$E30) | Z29: =IF($A30="","",IF(X29>=0.5,"Continuation Up",IF(X29<=-0.5,"Pullback","Digest")))
X30: =IF($A31="","",$M31) | Y30: =IF($A31="","",$E31) | Z30: =IF($A31="","",IF(X30>=0.5,"Continuation Up",IF(X30<=-0.5,"Pullback","Digest")))
X31: =IF($A32="","",$M32) | Y31: =IF($A32="","",$E32) | Z31: =IF($A32="","",IF(X31>=0.5,"Continuation Up",IF(X31<=-0.5,"Pullback","Digest")))
X32: =IF($A33="","",$M33) | Y32: =IF($A33="","",$E33) | Z32: =IF($A33="","",IF(X32>=0.5,"Continuation Up",IF(X32<=-0.5,"Pullback","Digest")))
X33: =IF($A34="","",$M34) | Y33: =IF($A34="","",$E34) | Z33: =IF($A34="","",IF(X33>=0.5,"Continuation Up",IF(X33<=-0.5,"Pullback","Digest")))
... X94: =IF($A95="","",$M95) | Y94: =IF($A95="","",$E95) | Z94: =IF($A95="","",IF(X94>=0.5,"Continuation Up",IF(X94<=-0.5,"Pullback","Digest")))

Sheet AutoScore
A1: Ticker | B1: RefPrice | C1: Price | D1: High | E1: Low | F1: ChangeAbs | G1: ChangePct | H1: Volume | I1: Value(Bil VND) | J1: Weight(optional) | K1: IsBank?(0/1) | L1: IsHeavyweights?(0/1) | M1: RangePos(0-1) | N1: NearHigh | O1: NearLow | P1: Up | Q1: Down | R1: Up>1% | S1: Down<-1% | T1: x | U1: WeightedRangePos | V1: InfluencePoints(raw) | W1: %Influence(raw) | X1: Proportion(raw)
A2: =Raw_VN30_Statistic!C2 -> ACB | B2: =Raw_VN30_Statistic!D2 -> 24.45 | C2: =Raw_VN30_Statistic!F2 -> 24.55 | D2: =Raw_VN30_Statistic!G2 -> 24.6 | E2: =Raw_VN30_Statistic!H2 -> 24.2 | F2: =IF(ISNUMBER(Raw_VN30_Statistic!J2),Raw_VN30_Statistic!J2,(C2-B2)) -> 100 | G2: =IF(ISNUMBER(Raw_VN30_Statistic!K2),Raw_VN30_Statistic!K2,IF(B2=0,0,F2/B2*100)) -> 0.41 | H2: =Raw_VN30_Statistic!P2 -> 14900900 | I2: =IF(Raw_VN30_Statistic!Q2="",0,Raw_VN30_Statistic!Q2/1000) -> 364.34 | J2: =IFERROR( _xlfn.XLOOKUP(A2,Raw_VN30_Influence!$B$2:$B$30,Raw_VN30_Influence!$G$2:$G$30) /SUM(Raw_VN30_Influence!$G$2:$G$31),"") -> 0.036661477 | K2: =IF(COUNTIF(Settings!$A:$A,A2)>0,1,0) -> 1 | L2: =IF(J2>=_xlfn.PERCENTILE.INC($J$2:$J$31,0.8),1,0) -> 0 | M2: =IF(D2=E2,0.5,MAX(0,MIN(1,(C2-E2)/(D2-E2)))) -> 0.875 | N2: =IF(M2>=0.8,1,0) -> 1 | O2: =IF(M2<=0.2,1,0) -> 0 | P2: =IF(G2>0,1,0) -> 1 | Q2: =IF(G2<0,1,0) -> 0 | R2: =IF(G2>=1,1,0) -> 0 | S2: =IF(G2<=-1,1,0) -> 0 | T2: =(IF(J2<>"",J2,IF(Raw_VN30_Statistic!R2="",0,Raw_VN30_Statistic!R2/SUM(Raw_VN30_Statistic!$R$2:$R$31))))*G2 -> 0.015031205 | U2: =(IF(J2<>"",J2,IF(Raw_VN30_Statistic!R2="",0,Raw_VN30_Statistic!R2/SUM(Raw_VN30_Statistic!$R$2:$R$31))))*M2 -> 0.032078792 | V2: =IFERROR(_xlfn.XLOOKUP(A2,[1]Raw_VN30_Influence!$B$2:$B$31,[1]Raw_VN30_Influence!$I$2:$I$31),"") -> 1.416 | W2: =IFERROR(_xlfn.XLOOKUP(A2,[1]Raw_VN30_Influence!$B$2:$B$31,[1]Raw_VN30_Influence!$H$2:$H$31),"") -> 0.069 | X2: =IFERROR(_xlfn.XLOOKUP(A2,[1]Raw_VN30_Influence!$B$2:$B$31,[1]Raw_VN30_Influence!$G$2:$G$31),"") -> 3.6727
A3: =Raw_VN30_Statistic!C3 -> BID | B3: =Raw_VN30_Statistic!D3 -> 48.45 | C3: =Raw_VN30_Statistic!F3 -> 47.9 | D3: =Raw_VN30_Statistic!G3 -> 49.1 | E3: =Raw_VN30_Statistic!H3 -> 47.5 | F3: =IF(ISNUMBER(Raw_VN30_Statistic!J3),Raw_VN30_Statistic!J3,(C3-B3)) -> -550 | G3: =IF(ISNUMBER(Raw_VN30_Statistic!K3),Raw_VN30_Statistic!K3,IF(B3=0,0,F3/B3*100)) -> -1.14 | H3: =Raw_VN30_Statistic!P3 -> 6519700 | I3: =IF(Raw_VN30_Statistic!Q3="",0,Raw_VN30_Statistic!Q3/1000) -> 312.959 | J3: =IFERROR( _xlfn.XLOOKUP(A3,Raw_VN30_Influence!$B$2:$B$30,Raw_VN30_Influence!$G$2:$G$30) /SUM(Raw_VN30_Influence!$G$2:$G$31),"") -> 0.0046010598 | K3: =IF(COUNTIF(Settings!$A:$A,A3)>0,1,0) -> 1 | L3: =IF(J3>=_xlfn.PERCENTILE.INC($J$2:$J$31,0.8),1,0) -> 0 | M3: =IF(D3=E3,0.5,MAX(0,MIN(1,(C3-E3)/(D3-E3)))) -> 0.25 | N3: =IF(M3>=0.8,1,0) -> 0 | O3: =IF(M3<=0.2,1,0) -> 0 | P3: =IF(G3>0,1,0) -> 0 | Q3: =IF(G3<0,1,0) -> 1 | R3: =IF(G3>=1,1,0) -> 0 | S3: =IF(G3<=-1,1,0) -> 1 | T3: =(IF(J3<>"",J3,IF(Raw_VN30_Statistic!R3="",0,Raw_VN30_Statistic!R3/SUM(Raw_VN30_Statistic!$R$2:$R$31))))*G3 -> -0.0052452082 | U3: =(IF(J3<>"",J3,IF(Raw_VN30_Statistic!R3="",0,Raw_VN30_Statistic!R3/SUM(Raw_VN30_Statistic!$R$2:$R$31))))*M3 -> 0.001150265 | V3: =IFERROR(_xlfn.XLOOKUP(A3,[1]Raw_VN30_Influence!$B$2:$B$31,[1]Raw_VN30_Influence!$I$2:$I$31),"") -> -0.049 | W3: =IFERROR(_xlfn.XLOOKUP(A3,[1]Raw_VN30_Influence!$B$2:$B$31,[1]Raw_VN30_Influence!$H$2:$H$31),"") -> -0.0024 | X3: =IFERROR(_xlfn.XLOOKUP(A3,[1]Raw_VN30_Influence!$B$2:$B$31,[1]Raw_VN30_Influence!$G$2:$G$31),"") -> 0.4686
A4: =Raw_VN30_Statistic!C4 -> CTG | B4: =Raw_VN30_Statistic!D4 -> 38.5 | C4: =Raw_VN30_Statistic!F4 -> 38.25 | D4: =Raw_VN30_Statistic!G4 -> 38.45 | E4: =Raw_VN30_Statistic!H4 -> 38.05 | F4: =IF(ISNUMBER(Raw_VN30_Statistic!J4),Raw_VN30_Statistic!J4,(C4-B4)) -> -250 | G4: =IF(ISNUMBER(Raw_VN30_Statistic!K4),Raw_VN30_Statistic!K4,IF(B4=0,0,F4/B4*100)) -> -0.65 | H4: =Raw_VN30_Statistic!P4 -> 10957400 | I4: =IF(Raw_VN30_Statistic!Q4="",0,Raw_VN30_Statistic!Q4/1000) -> 418.862 | J4: =IFERROR( _xlfn.XLOOKUP(A4,Raw_VN30_Influence!$B$2:$B$30,Raw_VN30_Influence!$G$2:$G$30) /SUM(Raw_VN30_Influence!$G$2:$G$31),"") -> 0.015241198 | K4: =IF(COUNTIF(Settings!$A:$A,A4)>0,1,0) -> 1 | L4: =IF(J4>=_xlfn.PERCENTILE.INC($J$2:$J$31,0.8),1,0) -> 0 | M4: =IF(D4=E4,0.5,MAX(0,MIN(1,(C4-E4)/(D4-E4)))) -> 0.5 | N4: =IF(M4>=0.8,1,0) -> 0 | O4: =IF(M4<=0.2,1,0) -> 0 | P4: =IF(G4>0,1,0) -> 0 | Q4: =IF(G4<0,1,0) -> 1 | R4: =IF(G4>=1,1,0) -> 0 | S4: =IF(G4<=-1,1,0) -> 0 | T4: =(IF(J4<>"",J4,IF(Raw_VN30_Statistic!R4="",0,Raw_VN30_Statistic!R4/SUM(Raw_VN30_Statistic!$R$2:$R$31))))*G4 -> -0.0099067788 | U4: =(IF(J4<>"",J4,IF(Raw_VN30_Statistic!R4="",0,Raw_VN30_Statistic!R4/SUM(Raw_VN30_Statistic!$R$2:$R$31))))*M4 -> 0.0076205991 | V4: =IFERROR(_xlfn.XLOOKUP(A4,[1]Raw_VN30_Influence!$B$2:$B$31,[1]Raw_VN30_Influence!$I$2:$I$31),"") -> 0.25 | W4: =IFERROR(_xlfn.XLOOKUP(A4,[1]Raw_VN30_Influence!$B$2:$B$31,[1]Raw_VN30_Influence!$H$2:$H$31),"") -> 0.0122 | X4: =IFERROR(_xlfn.XLOOKUP(A4,[1]Raw_VN30_Influence!$B$2:$B$31,[1]Raw_VN30_Influence!$G$2:$G$31),"") -> 1.5431
A5: =Raw_VN30_Statistic!C5 -> DGC | B5: =Raw_VN30_Statistic!D5 -> 73.6 | C5: =Raw_VN30_Statistic!F5 -> 73.8 | D5: =Raw_VN30_Statistic!G5 -> 74.5 | E5: =Raw_VN30_Statistic!H5 -> 72 | F5: =IF(ISNUMBER(Raw_VN30_Statistic!J5),Raw_VN30_Statistic!J5,(C5-B5)) -> 200 | G5: =IF(ISNUMBER(Raw_VN30_Statistic!K5),Raw_VN30_Statistic!K5,IF(B5=0,0,F5/B5*100)) -> 0.27 | H5: =Raw_VN30_Statistic!P5 -> 4426300 | I5: =IF(Raw_VN30_Statistic!Q5="",0,Raw_VN30_Statistic!Q5/1000) -> 327.067 | J5: =IFERROR( _xlfn.XLOOKUP(A5,Raw_VN30_Influence!$B$2:$B$30,Raw_VN30_Influence!$G$2:$G$30) /SUM(Raw_VN30_Influence!$G$2:$G$31),"") -> 0.012708165 | K5: =IF(COUNTIF(Settings!$A:$A,A5)>0,1,0) -> 0 | L5: =IF(J5>=_xlfn.PERCENTILE.INC($J$2:$J$31,0.8),1,0) -> 0 | M5: =IF(D5=E5,0.5,MAX(0,MIN(1,(C5-E5)/(D5-E5)))) -> 0.72 | N5: =IF(M5>=0.8,1,0) -> 0 | O5: =IF(M5<=0.2,1,0) -> 0 | P5: =IF(G5>0,1,0) -> 1 | Q5: =IF(G5<0,1,0) -> 0 | R5: =IF(G5>=1,1,0) -> 0 | S5: =IF(G5<=-1,1,0) -> 0 | T5: =(IF(J5<>"",J5,IF(Raw_VN30_Statistic!R5="",0,Raw_VN30_Statistic!R5/SUM(Raw_VN30_Statistic!$R$2:$R$31))))*G5 -> 0.0034312046 | U5: =(IF(J5<>"",J5,IF(Raw_VN30_Statistic!R5="",0,Raw_VN30_Statistic!R5/SUM(Raw_VN30_Statistic!$R$2:$R$31))))*M5 -> 0.0091498789 | V5: =IFERROR(_xlfn.XLOOKUP(A5,[1]Raw_VN30_Influence!$B$2:$B$31,[1]Raw_VN30_Influence!$I$2:$I$31),"") -> 0.324 | W5: =IFERROR(_xlfn.XLOOKUP(A5,[1]Raw_VN30_Influence!$B$2:$B$31,[1]Raw_VN30_Influence!$H$2:$H$31),"") -> 0.0158 | X5: =IFERROR(_xlfn.XLOOKUP(A5,[1]Raw_VN30_Influence!$B$2:$B$31,[1]Raw_VN30_Influence!$G$2:$G$31),"") -> 1.3164
A6: =Raw_VN30_Statistic!C6 -> FPT | B6: =Raw_VN30_Statistic!D6 -> 90.5 | C6: =Raw_VN30_Statistic!F6 -> 92.9 | D6: =Raw_VN30_Statistic!G6 -> 93.5 | E6: =Raw_VN30_Statistic!H6 -> 90.3 | F6: =IF(ISNUMBER(Raw_VN30_Statistic!J6),Raw_VN30_Statistic!J6,(C6-B6)) -> 2400 | G6: =IF(ISNUMBER(Raw_VN30_Statistic!K6),Raw_VN30_Statistic!K6,IF(B6=0,0,F6/B6*100)) -> 2.65 | H6: =Raw_VN30_Statistic!P6 -> 19505600 | I6: =IF(Raw_VN30_Statistic!Q6="",0,Raw_VN30_Statistic!Q6/1000) -> 1788.467 | J6: =IFERROR( _xlfn.XLOOKUP(A6,Raw_VN30_Influence!$B$2:$B$30,Raw_VN30_Influence!$G$2:$G$30) /SUM(Raw_VN30_Influence!$G$2:$G$31),"") -> 0.089720166 | K6: =IF(COUNTIF(Settings!$A:$A,A6)>0,1,0) -> 0 | L6: =IF(J6>=_xlfn.PERCENTILE.INC($J$2:$J$31,0.8),1,0) -> 1 | M6: =IF(D6=E6,0.5,MAX(0,MIN(1,(C6-E6)/(D6-E6)))) -> 0.8125 | N6: =IF(M6>=0.8,1,0) -> 1 | O6: =IF(M6<=0.2,1,0) -> 0 | P6: =IF(G6>0,1,0) -> 1 | Q6: =IF(G6<0,1,0) -> 0 | R6: =IF(G6>=1,1,0) -> 1 | S6: =IF(G6<=-1,1,0) -> 0 | T6: =(IF(J6<>"",J6,IF(Raw_VN30_Statistic!R6="",0,Raw_VN30_Statistic!R6/SUM(Raw_VN30_Statistic!$R$2:$R$31))))*G6 -> 0.23775844 | U6: =(IF(J6<>"",J6,IF(Raw_VN30_Statistic!R6="",0,Raw_VN30_Statistic!R6/SUM(Raw_VN30_Statistic!$R$2:$R$31))))*M6 -> 0.072897635 | V6: =IFERROR(_xlfn.XLOOKUP(A6,[1]Raw_VN30_Influence!$B$2:$B$31,[1]Raw_VN30_Influence!$I$2:$I$31),"") -> -6.5326 | W6: =IFERROR(_xlfn.XLOOKUP(A6,[1]Raw_VN30_Influence!$B$2:$B$31,[1]Raw_VN30_Influence!$H$2:$H$31),"") -> -0.3185 | X6: =IFERROR(_xlfn.XLOOKUP(A6,[1]Raw_VN30_Influence!$B$2:$B$31,[1]Raw_VN30_Influence!$G$2:$G$31),"") -> 8.6557
A7: =Raw_VN30_Statistic!C7 -> GAS | B7: =Raw_VN30_Statistic!D7 -> 106 | C7: =Raw_VN30_Statistic!F7 -> 107.9 | D7: =Raw_VN30_Statistic!G7 -> 111.9 | E7: =Raw_VN30_Statistic!H7 -> 105.5 | F7: =IF(ISNUMBER(Raw_VN30_Statistic!J7),Raw_VN30_Statistic!J7,(C7-B7)) -> 1900 | G7: =IF(ISNUMBER(Raw_VN30_Statistic!K7),Raw_VN30_Statistic!K7,IF(B7=0,0,F7/B7*100)) -> 1.79 | H7: =Raw_VN30_Statistic!P7 -> 2827100 | I7: =IF(Raw_VN30_Statistic!Q7="",0,Raw_VN30_Statistic!Q7/1000) -> 304.213 | J7: =IFERROR( _xlfn.XLOOKUP(A7,Raw_VN30_Influence!$B$2:$B$30,Raw_VN30_Influence!$G$2:$G$30) /SUM(Raw_VN30_Influence!$G$2:$G$31),"") -> 0.0098371279 | K7: =IF(COUNTIF(Settings!$A:$A,A7)>0,1,0) -> 0 | L7: =IF(J7>=_xlfn.PERCENTILE.INC($J$2:$J$31,0.8),1,0) -> 0 | M7: =IF(D7=E7,0.5,MAX(0,MIN(1,(C7-E7)/(D7-E7)))) -> 0.375 | N7: =IF(M7>=0.8,1,0) -> 0 | O7: =IF(M7<=0.2,1,0) -> 0 | P7: =IF(G7>0,1,0) -> 1 | Q7: =IF(G7<0,1,0) -> 0 | R7: =IF(G7>=1,1,0) -> 1 | S7: =IF(G7<=-1,1,0) -> 0 | T7: =(IF(J7<>"",J7,IF(Raw_VN30_Statistic!R7="",0,Raw_VN30_Statistic!R7/SUM(Raw_VN30_Statistic!$R$2:$R$31))))*G7 -> 0.017608459 | U7: =(IF(J7<>"",J7,IF(Raw_VN30_Statistic!R7="",0,Raw_VN30_Statistic!R7/SUM(Raw_VN30_Statistic!$R$2:$R$31))))*M7 -> 0.003688923 | V7: =IFERROR(_xlfn.XLOOKUP(A7,[1]Raw_VN30_Influence!$B$2:$B$31,[1]Raw_VN30_Influence!$I$2:$I$31),"") -> -0.0931 | W7: =IFERROR(_xlfn.XLOOKUP(A7,[1]Raw_VN30_Influence!$B$2:$B$31,[1]Raw_VN30_Influence!$H$2:$H$31),"") -> -0.0045 | X7: =IFERROR(_xlfn.XLOOKUP(A7,[1]Raw_VN30_Influence!$B$2:$B$31,[1]Raw_VN30_Influence!$G$2:$G$31),"") -> 1.0088
A8: =Raw_VN30_Statistic!C8 -> GVR | B8: =Raw_VN30_Statistic!D8 -> 40.8 | C8: =Raw_VN30_Statistic!F8 -> 40 | D8: =Raw_VN30_Statistic!G8 -> 42.3 | E8: =Raw_VN30_Statistic!H8 -> 39.8 | F8: =IF(ISNUMBER(Raw_VN30_Statistic!J8),Raw_VN30_Statistic!J8,(C8-B8)) -> -800 | G8: =IF(ISNUMBER(Raw_VN30_Statistic!K8),Raw_VN30_Statistic!K8,IF(B8=0,0,F8/B8*100)) -> -1.96 | H8: =Raw_VN30_Statistic!P8 -> 6357900 | I8: =IF(Raw_VN30_Statistic!Q8="",0,Raw_VN30_Statistic!Q8/1000) -> 259.188 | J8: =IFERROR( _xlfn.XLOOKUP(A8,Raw_VN30_Influence!$B$2:$B$30,Raw_VN30_Influence!$G$2:$G$30) /SUM(Raw_VN30_Influence!$G$2:$G$31),"") -> 0.0048360629 | K8: =IF(COUNTIF(Settings!$A:$A,A8)>0,1,0) -> 0 | L8: =IF(J8>=_xlfn.PERCENTILE.INC($J$2:$J$31,0.8),1,0) -> 0 | M8: =IF(D8=E8,0.5,MAX(0,MIN(1,(C8-E8)/(D8-E8)))) -> 0.08 | N8: =IF(M8>=0.8,1,0) -> 0 | O8: =IF(M8<=0.2,1,0) -> 1 | P8: =IF(G8>0,1,0) -> 0 | Q8: =IF(G8<0,1,0) -> 1 | R8: =IF(G8>=1,1,0) -> 0 | S8: =IF(G8<=-1,1,0) -> 1 | T8: =(IF(J8<>"",J8,IF(Raw_VN30_Statistic!R8="",0,Raw_VN30_Statistic!R8/SUM(Raw_VN30_Statistic!$R$2:$R$31))))*G8 -> -0.0094786832 | U8: =(IF(J8<>"",J8,IF(Raw_VN30_Statistic!R8="",0,Raw_VN30_Statistic!R8/SUM(Raw_VN30_Statistic!$R$2:$R$31))))*M8 -> 0.00038688503 | V8: =IFERROR(_xlfn.XLOOKUP(A8,[1]Raw_VN30_Influence!$B$2:$B$31,[1]Raw_VN30_Influence!$I$2:$I$31),"") -> 0.7336 | W8: =IFERROR(_xlfn.XLOOKUP(A8,[1]Raw_VN30_Influence!$B$2:$B$31,[1]Raw_VN30_Influence!$H$2:$H$31),"") -> 0.0358 | X8: =IFERROR(_xlfn.XLOOKUP(A8,[1]Raw_VN30_Influence!$B$2:$B$31,[1]Raw_VN30_Influence!$G$2:$G$31),"") -> 0.5132
A9: =Raw_VN30_Statistic!C9 -> HDB | B9: =Raw_VN30_Statistic!D9 -> 28.4 | C9: =Raw_VN30_Statistic!F9 -> 27.95 | D9: =Raw_VN30_Statistic!G9 -> 28.4 | E9: =Raw_VN30_Statistic!H9 -> 27.95 | F9: =IF(ISNUMBER(Raw_VN30_Statistic!J9),Raw_VN30_Statistic!J9,(C9-B9)) -> -450 | G9: =IF(ISNUMBER(Raw_VN30_Statistic!K9),Raw_VN30_Statistic!K9,IF(B9=0,0,F9/B9*100)) -> -1.58 | H9: =Raw_VN30_Statistic!P9 -> 21074171 | I9: =IF(Raw_VN30_Statistic!Q9="",0,Raw_VN30_Statistic!Q9/1000) -> 591.089 | J9: =IFERROR( _xlfn.XLOOKUP(A9,Raw_VN30_Influence!$B$2:$B$30,Raw_VN30_Influence!$G$2:$G$30) /SUM(Raw_VN30_Influence!$G$2:$G$31),"") -> 0.038278498 | K9: =IF(COUNTIF(Settings!$A:$A,A9)>0,1,0) -> 1 | L9: =IF(J9>=_xlfn.PERCENTILE.INC($J$2:$J$31,0.8),1,0) -> 0 | M9: =IF(D9=E9,0.5,MAX(0,MIN(1,(C9-E9)/(D9-E9)))) -> 0 | N9: =IF(M9>=0.8,1,0) -> 0 | O9: =IF(M9<=0.2,1,0) -> 1 | P9: =IF(G9>0,1,0) -> 0 | Q9: =IF(G9<0,1,0) -> 1 | R9: =IF(G9>=1,1,0) -> 0 | S9: =IF(G9<=-1,1,0) -> 1 | T9: =(IF(J9<>"",J9,IF(Raw_VN30_Statistic!R9="",0,Raw_VN30_Statistic!R9/SUM(Raw_VN30_Statistic!$R$2:$R$31))))*G9 -> -0.060480026 | U9: =(IF(J9<>"",J9,IF(Raw_VN30_Statistic!R9="",0,Raw_VN30_Statistic!R9/SUM(Raw_VN30_Statistic!$R$2:$R$31))))*M9 -> 0 | V9: =IFERROR(_xlfn.XLOOKUP(A9,[1]Raw_VN30_Influence!$B$2:$B$31,[1]Raw_VN30_Influence!$I$2:$I$31),"") -> -0.1447 | W9: =IFERROR(_xlfn.XLOOKUP(A9,[1]Raw_VN30_Influence!$B$2:$B$31,[1]Raw_VN30_Influence!$H$2:$H$31),"") -> -0.0071 | X9: =IFERROR(_xlfn.XLOOKUP(A9,[1]Raw_VN30_Influence!$B$2:$B$31,[1]Raw_VN30_Influence!$G$2:$G$31),"") -> 3.9193
A10: =Raw_VN30_Statistic!C10 -> HPG | B10: =Raw_VN30_Statistic!D10 -> 29.4 | C10: =Raw_VN30_Statistic!F10 -> 28.8 | D10: =Raw_VN30_Statistic!G10 -> 29.4 | E10: =Raw_VN30_Statistic!H10 -> 28.8 | F10: =IF(ISNUMBER(Raw_VN30_Statistic!J10),Raw_VN30_Statistic!J10,(C10-B10)) -> -600 | G10: =IF(ISNUMBER(Raw_VN30_Statistic!K10),Raw_VN30_Statistic!K10,IF(B10=0,0,F10/B10*100)) -> -2.04 | H10: =Raw_VN30_Statistic!P10 -> 50056500 | I10: =IF(Raw_VN30_Statistic!Q10="",0,Raw_VN30_Statistic!Q10/1000) -> 1452.997 | J10: =IFERROR( _xlfn.XLOOKUP(A10,Raw_VN30_Influence!$B$2:$B$30,Raw_VN30_Influence!$G$2:$G$30) /SUM(Raw_VN30_Influence!$G$2:$G$31),"") | K10: =IF(COUNTIF(Settings!$A:$A,A10)>0,1,0) -> 0 | L10: =IF(J10>=_xlfn.PERCENTILE.INC($J$2:$J$31,0.8),1,0) -> 1 | M10: =IF(D10=E10,0.5,MAX(0,MIN(1,(C10-E10)/(D10-E10)))) -> 0 | N10: =IF(M10>=0.8,1,0) -> 0 | O10: =IF(M10<=0.2,1,0) -> 1 | P10: =IF(G10>0,1,0) -> 0 | Q10: =IF(G10<0,1,0) -> 1 | R10: =IF(G10>=1,1,0) -> 0 | S10: =IF(G10<=-1,1,0) -> 1 | T10: =(IF(J10<>"",J10,IF(Raw_VN30_Statistic!R10="",0,Raw_VN30_Statistic!R10/SUM(Raw_VN30_Statistic!$R$2:$R$31))))*G10 -> -0.072992768 | U10: =(IF(J10<>"",J10,IF(Raw_VN30_Statistic!R10="",0,Raw_VN30_Statistic!R10/SUM(Raw_VN30_Statistic!$R$2:$R$31))))*M10 -> 0 | V10: =IFERROR(_xlfn.XLOOKUP(A10,[1]Raw_VN30_Influence!$B$2:$B$31,[1]Raw_VN30_Influence!$I$2:$I$31),"") -> 6.8068 | W10: =IFERROR(_xlfn.XLOOKUP(A10,[1]Raw_VN30_Influence!$B$2:$B$31,[1]Raw_VN30_Influence!$H$2:$H$31),"") -> 0.3319 | X10: =IFERROR(_xlfn.XLOOKUP(A10,[1]Raw_VN30_Influence!$B$2:$B$31,[1]Raw_VN30_Influence!$G$2:$G$31),"") -> 9.4023
A11: =Raw_VN30_Statistic!C11 -> LPB | B11: =Raw_VN30_Statistic!D11 -> 43.15 | C11: =Raw_VN30_Statistic!F11 -> 43.05 | D11: =Raw_VN30_Statistic!G11 -> 44.3 | E11: =Raw_VN30_Statistic!H11 -> 42.75 | F11: =IF(ISNUMBER(Raw_VN30_Statistic!J11),Raw_VN30_Statistic!J11,(C11-B11)) -> -100 | G11: =IF(ISNUMBER(Raw_VN30_Statistic!K11),Raw_VN30_Statistic!K11,IF(B11=0,0,F11/B11*100)) -> -0.23 | H11: =Raw_VN30_Statistic!P11 -> 1509700 | I11: =IF(Raw_VN30_Statistic!Q11="",0,Raw_VN30_Statistic!Q11/1000) -> 65.348 | J11: =IFERROR( _xlfn.XLOOKUP(A11,Raw_VN30_Influence!$B$2:$B$30,Raw_VN30_Influence!$G$2:$G$30) /SUM(Raw_VN30_Influence!$G$2:$G$31),"") -> 0.041785543 | K11: =IF(COUNTIF(Settings!$A:$A,A11)>0,1,0) -> 1 | L11: =IF(J11>=_xlfn.PERCENTILE.INC($J$2:$J$31,0.8),1,0) -> 0 | M11: =IF(D11=E11,0.5,MAX(0,MIN(1,(C11-E11)/(D11-E11)))) -> 0.19354839 | N11: =IF(M11>=0.8,1,0) -> 0 | O11: =IF(M11<=0.2,1,0) -> 1 | P11: =IF(G11>0,1,0) -> 0 | Q11: =IF(G11<0,1,0) -> 1 | R11: =IF(G11>=1,1,0) -> 0 | S11: =IF(G11<=-1,1,0) -> 0 | T11: =(IF(J11<>"",J11,IF(Raw_VN30_Statistic!R11="",0,Raw_VN30_Statistic!R11/SUM(Raw_VN30_Statistic!$R$2:$R$31))))*G11 -> -0.0096106749 | U11: =(IF(J11<>"",J11,IF(Raw_VN30_Statistic!R11="",0,Raw_VN30_Statistic!R11/SUM(Raw_VN30_Statistic!$R$2:$R$31))))*M11 -> 0.0080875245 | V11: =IFERROR(_xlfn.XLOOKUP(A11,[1]Raw_VN30_Influence!$B$2:$B$31,[1]Raw_VN30_Influence!$I$2:$I$31),"") -> -0.5929 | W11: =IFERROR(_xlfn.XLOOKUP(A11,[1]Raw_VN30_Influence!$B$2:$B$31,[1]Raw_VN30_Influence!$H$2:$H$31),"") -> -0.0289 | X11: =IFERROR(_xlfn.XLOOKUP(A11,[1]Raw_VN30_Influence!$B$2:$B$31,[1]Raw_VN30_Influence!$G$2:$G$31),"") -> 4.13
A12: =Raw_VN30_Statistic!C12 -> MBB | B12: =Raw_VN30_Statistic!D12 -> 28.8 | C12: =Raw_VN30_Statistic!F12 -> 28.5 | D12: =Raw_VN30_Statistic!G12 -> 28.85 | E12: =Raw_VN30_Statistic!H12 -> 28.5 | F12: =IF(ISNUMBER(Raw_VN30_Statistic!J12),Raw_VN30_Statistic!J12,(C12-B12)) -> -300 | G12: =IF(ISNUMBER(Raw_VN30_Statistic!K12),Raw_VN30_Statistic!K12,IF(B12=0,0,F12/B12*100)) -> -1.04 | H12: =Raw_VN30_Statistic!P12 -> 19533600 | I12: =IF(Raw_VN30_Statistic!Q12="",0,Raw_VN30_Statistic!Q12/1000) -> 561.367 | J12: =IFERROR( _xlfn.XLOOKUP(A12,Raw_VN30_Influence!$B$2:$B$30,Raw_VN30_Influence!$G$2:$G$30) /SUM(Raw_VN30_Influence!$G$2:$G$31),"") -> 0.03925851 | K12: =IF(COUNTIF(Settings!$A:$A,A12)>0,1,0) -> 1 | L12: =IF(J12>=_xlfn.PERCENTILE.INC($J$2:$J$31,0.8),1,0) -> 0 | M12: =IF(D12=E12,0.5,MAX(0,MIN(1,(C12-E12)/(D12-E12)))) -> 0 | N12: =IF(M12>=0.8,1,0) -> 0 | O12: =IF(M12<=0.2,1,0) -> 1 | P12: =IF(G12>0,1,0) -> 0 | Q12: =IF(G12<0,1,0) -> 1 | R12: =IF(G12>=1,1,0) -> 0 | S12: =IF(G12<=-1,1,0) -> 1 | T12: =(IF(J12<>"",J12,IF(Raw_VN30_Statistic!R12="",0,Raw_VN30_Statistic!R12/SUM(Raw_VN30_Statistic!$R$2:$R$31))))*G12 -> -0.040828851 | U12: =(IF(J12<>"",J12,IF(Raw_VN30_Statistic!R12="",0,Raw_VN30_Statistic!R12/SUM(Raw_VN30_Statistic!$R$2:$R$31))))*M12 -> 0 | V12: =IFERROR(_xlfn.XLOOKUP(A12,[1]Raw_VN30_Influence!$B$2:$B$31,[1]Raw_VN30_Influence!$I$2:$I$31),"") -> 1.4461 | W12: =IFERROR(_xlfn.XLOOKUP(A12,[1]Raw_VN30_Influence!$B$2:$B$31,[1]Raw_VN30_Influence!$H$2:$H$31),"") -> 0.0705 | X12: =IFERROR(_xlfn.XLOOKUP(A12,[1]Raw_VN30_Influence!$B$2:$B$31,[1]Raw_VN30_Influence!$G$2:$G$31),"") -> 3.9837
A13: =Raw_VN30_Statistic!C13 -> MSN | B13: =Raw_VN30_Statistic!D13 -> 80.4 | C13: =Raw_VN30_Statistic!F13 -> 79 | D13: =Raw_VN30_Statistic!G13 -> 80.6 | E13: =Raw_VN30_Statistic!H13 -> 79 | F13: =IF(ISNUMBER(Raw_VN30_Statistic!J13),Raw_VN30_Statistic!J13,(C13-B13)) -> -1400 | G13: =IF(ISNUMBER(Raw_VN30_Statistic!K13),Raw_VN30_Statistic!K13,IF(B13=0,0,F13/B13*100)) -> -1.74 | H13: =Raw_VN30_Statistic!P13 -> 5053900 | I13: =IF(Raw_VN30_Statistic!Q13="",0,Raw_VN30_Statistic!Q13/1000) -> 402.55 | J13: =IFERROR( _xlfn.XLOOKUP(A13,Raw_VN30_Influence!$B$2:$B$30,Raw_VN30_Influence!$G$2:$G$30) /SUM(Raw_VN30_Influence!$G$2:$G$31),"") -> 0.051792673 | K13: =IF(COUNTIF(Settings!$A:$A,A13)>0,1,0) -> 0 | L13: =IF(J13>=_xlfn.PERCENTILE.INC($J$2:$J$31,0.8),1,0) -> 1 | M13: =IF(D13=E13,0.5,MAX(0,MIN(1,(C13-E13)/(D13-E13)))) -> 0 | N13: =IF(M13>=0.8,1,0) -> 0 | O13: =IF(M13<=0.2,1,0) -> 1 | P13: =IF(G13>0,1,0) -> 0 | Q13: =IF(G13<0,1,0) -> 1 | R13: =IF(G13>=1,1,0) -> 0 | S13: =IF(G13<=-1,1,0) -> 1 | T13: =(IF(J13<>"",J13,IF(Raw_VN30_Statistic!R13="",0,Raw_VN30_Statistic!R13/SUM(Raw_VN30_Statistic!$R$2:$R$31))))*G13 -> -0.090119252 | U13: =(IF(J13<>"",J13,IF(Raw_VN30_Statistic!R13="",0,Raw_VN30_Statistic!R13/SUM(Raw_VN30_Statistic!$R$2:$R$31))))*M13 -> 0 | V13: =IFERROR(_xlfn.XLOOKUP(A13,[1]Raw_VN30_Influence!$B$2:$B$31,[1]Raw_VN30_Influence!$I$2:$I$31),"") -> -0.8037 | W13: =IFERROR(_xlfn.XLOOKUP(A13,[1]Raw_VN30_Influence!$B$2:$B$31,[1]Raw_VN30_Influence!$H$2:$H$31),"") -> -0.0392 | X13: =IFERROR(_xlfn.XLOOKUP(A13,[1]Raw_VN30_Influence!$B$2:$B$31,[1]Raw_VN30_Influence!$G$2:$G$31),"") -> 5.2955
... A31: =Raw_VN30_Statistic!C31 -> VRE | B31: =Raw_VN30_Statistic!D31 -> 29.75 | C31: =Raw_VN30_Statistic!F31 -> 29.05 | D31: =Raw_VN30_Statistic!G31 -> 29.8 | E31: =Raw_VN30_Statistic!H31 -> 29.05 | F31: =IF(ISNUMBER(Raw_VN30_Statistic!J31),Raw_VN30_Statistic!J31,(C31-B31)) -> -700 | G31: =IF(ISNUMBER(Raw_VN30_Statistic!K31),Raw_VN30_Statistic!K31,IF(B31=0,0,F31/B31*100)) -> -2.35 | H31: =Raw_VN30_Statistic!P31 -> 3120400 | I31: =IF(Raw_VN30_Statistic!Q31="",0,Raw_VN30_Statistic!Q31/1000) -> 91.252 | J31: =IFERROR( _xlfn.XLOOKUP(A31,Raw_VN30_Influence!$B$2:$B$30,Raw_VN30_Influence!$G$2:$G$30) /SUM(Raw_VN30_Influence!$G$2:$G$31),"") -> 0.019953259 | K31: =IF(COUNTIF(Settings!$A:$A,A31)>0,1,0) -> 0 | L31: =IF(J31>=_xlfn.PERCENTILE.INC($J$2:$J$31,0.8),1,0) -> 0 | M31: =IF(D31=E31,0.5,MAX(0,MIN(1,(C31-E31)/(D31-E31)))) -> 0 | N31: =IF(M31>=0.8,1,0) -> 0 | O31: =IF(M31<=0.2,1,0) -> 1 | P31: =IF(G31>0,1,0) -> 0 | Q31: =IF(G31<0,1,0) -> 1 | R31: =IF(G31>=1,1,0) -> 0 | S31: =IF(G31<=-1,1,0) -> 1 | T31: =(IF(J31<>"",J31,IF(Raw_VN30_Statistic!R31="",0,Raw_VN30_Statistic!R31/SUM(Raw_VN30_Statistic!$R$2:$R$31))))*G31 -> -0.04689016 | U31: =(IF(J31<>"",J31,IF(Raw_VN30_Statistic!R31="",0,Raw_VN30_Statistic!R31/SUM(Raw_VN30_Statistic!$R$2:$R$31))))*M31 -> 0 | V31: =IFERROR(_xlfn.XLOOKUP(A31,[1]Raw_VN30_Influence!$B$2:$B$31,[1]Raw_VN30_Influence!$I$2:$I$31),"") -> -1.3026 | W31: =IFERROR(_xlfn.XLOOKUP(A31,[1]Raw_VN30_Influence!$B$2:$B$31,[1]Raw_VN30_Influence!$H$2:$H$31),"") -> -0.0635 | X31: =IFERROR(_xlfn.XLOOKUP(A31,[1]Raw_VN30_Influence!$B$2:$B$31,[1]Raw_VN30_Influence!$G$2:$G$31),"") -> 1.9725

Sheet Settings
A1: Bank tickers (IsBank=1) | E1: Notes
